Workbook
Name insightCritical: '03_Calculations'!$I$25
Name insightDriver: '03_Calculations'!$I$26
Name insightOpportunity: '03_Calculations'!$I$28
Name insightWarning: '03_Calculations'!$I$27
Name kpiChurned: '03_Calculations'!$C$6
Name kpiChurnRate: '03_Calculations'!$C$8
Name kpiExisting: '03_Calculations'!$C$5
Name kpiMRVL: '03_Calculations'!$C$10
Name kpiRetained: '03_Calculations'!$C$7
Name kpiRetentionRate: '03_Calculations'!$C$9
Name nativePivotsReady: '03_Calculations'!$H$2

Sheet 01_Dashboard
A1: CUSTOMER RETENTION INTELLIGENCE | Q1: Q2 2022 • CALIFORNIA
A3: Executive churn health • concentration • drivers • retention opportunity | Q3: 7,043 customers | 454 joined | rates exclude Joined
A4: CONTRACT | I4: TENURE BAND | Q4: INTERNET TYPE
A5: Month-to-Month • One Year • Two Year Native slicer is created here by setup_dashboard.bas | I5: 0–6 months → 49–72 months Native slicer is created here by setup_dashboard.bas | Q5: Fiber Optic • Cable • DSL • (blank = no internet) Native slicer is created here by setup_dashboard.bas
A8: EXISTING CUSTOMERS | E8: CHURNED CUSTOMERS | I8: RETAINED CUSTOMERS | M8: CHURN RATE | Q8: RETENTION RATE | U8: MRVL
A9: =kpiExisting -> 6589 | E9: =kpiChurned -> 1869 | I9: =kpiRetained -> 4720 | M9: =kpiChurnRate -> 0.28365458 | Q9: =kpiRetentionRate -> 0.71634542 | U9: =kpiMRVL -> 137086.65
A11: Active base | E11: Exited | I11: Stayed | M11: Churned ÷ Existing | Q11: Retained ÷ Existing | U11: Monthly value lost
A13: MAIN ANALYSIS | Concentration • associated characteristics • stated reasons • retention priority
A14: CONTRACT × TENURE CHURN CONCENTRATION | Q14: CHURN RATE BY INTERNET TYPE
E15: Month-to-Month | I15: One Year | M15: Two Year | Q15: Which internet technology is associated with elevated churn?
A16: 0-6 months | E16: =IF(nativePivotsReady,IFERROR(GETPIVOTDATA("Churn Rate",'02_Pivots'!$A$52,"Tenure_Band","0-6 months","Contract","Month-to-Month"),""),0.8133472367049009) -> 0.81334724 | I16: =IF(nativePivotsReady,IFERROR(GETPIVOTDATA("Churn Rate",'02_Pivots'!$A$52,"Tenure_Band","0-6 months","Contract","One Year"),""),0.14285714285714285) -> 0.14285714 | M16: =IF(nativePivotsReady,IFERROR(GETPIVOTDATA("Churn Rate",'02_Pivots'!$A$52,"Tenure_Band","0-6 months","Contract","Two Year"),""),0.0) -> 0 | Q16: BASELINE PREVIEW • NATIVE INTERACTIVITY ADDED BY VBA
E17: =IF(nativePivotsReady,IFERROR(GETPIVOTDATA("Existing Customers",'02_Pivots'!$A$52,"Tenure_Band","0-6 months","Contract","Month-to-Month"),""),959) -> 959 | I17: =IF(nativePivotsReady,IFERROR(GETPIVOTDATA("Existing Customers",'02_Pivots'!$A$52,"Tenure_Band","0-6 months","Contract","One Year"),""),28) -> 28 | M17: =IF(nativePivotsReady,IFERROR(GETPIVOTDATA("Existing Customers",'02_Pivots'!$A$52,"Tenure_Band","0-6 months","Contract","Two Year"),""),29) -> 29
A18: 7-12 months | E18: =IF(nativePivotsReady,IFERROR(GETPIVOTDATA("Churn Rate",'02_Pivots'!$A$52,"Tenure_Band","7-12 months","Contract","Month-to-Month"),""),0.4468864468864469) -> 0.44688645 | I18: =IF(nativePivotsReady,IFERROR(GETPIVOTDATA("Churn Rate",'02_Pivots'!$A$52,"Tenure_Band","7-12 months","Contract","One Year"),""),0.09574468085106383) -> 0.095744681 | M18: =IF(nativePivotsReady,IFERROR(GETPIVOTDATA("Churn Rate",'02_Pivots'!$A$52,"Tenure_Band","7-12 months","Contract","Two Year"),""),0.0) -> 0 | Q18: Fiber Optic | W18: 0.42126789
E19: =IF(nativePivotsReady,IFERROR(GETPIVOTDATA("Existing Customers",'02_Pivots'!$A$52,"Tenure_Band","7-12 months","Contract","Month-to-Month"),""),546) -> 546 | I19: =IF(nativePivotsReady,IFERROR(GETPIVOTDATA("Existing Customers",'02_Pivots'!$A$52,"Tenure_Band","7-12 months","Contract","One Year"),""),94) -> 94 | M19: =IF(nativePivotsReady,IFERROR(GETPIVOTDATA("Existing Customers",'02_Pivots'!$A$52,"Tenure_Band","7-12 months","Contract","Two Year"),""),76) -> 76
A20: 13-24 months | E20: =IF(nativePivotsReady,IFERROR(GETPIVOTDATA("Churn Rate",'02_Pivots'!$A$52,"Tenure_Band","13-24 months","Contract","Month-to-Month"),""),0.40524781341107874) -> 0.40524781 | I20: =IF(nativePivotsReady,IFERROR(GETPIVOTDATA("Churn Rate",'02_Pivots'!$A$52,"Tenure_Band","13-24 months","Contract","One Year"),""),0.07441860465116279) -> 0.074418605 | M20: =IF(nativePivotsReady,IFERROR(GETPIVOTDATA("Churn Rate",'02_Pivots'!$A$52,"Tenure_Band","13-24 months","Contract","Two Year"),""),0.0) -> 0
E21: =IF(nativePivotsReady,IFERROR(GETPIVOTDATA("Existing Customers",'02_Pivots'!$A$52,"Tenure_Band","13-24 months","Contract","Month-to-Month"),""),686) -> 686 | I21: =IF(nativePivotsReady,IFERROR(GETPIVOTDATA("Existing Customers",'02_Pivots'!$A$52,"Tenure_Band","13-24 months","Contract","One Year"),""),215) -> 215 | M21: =IF(nativePivotsReady,IFERROR(GETPIVOTDATA("Existing Customers",'02_Pivots'!$A$52,"Tenure_Band","13-24 months","Contract","Two Year"),""),123) -> 123 | Q21: Cable | W21: 0.2751938
A22: 25-36 months | E22: =IF(nativePivotsReady,IFERROR(GETPIVOTDATA("Churn Rate",'02_Pivots'!$A$52,"Tenure_Band","25-36 months","Contract","Month-to-Month"),""),0.3648960739030023) -> 0.36489607 | I22: =IF(nativePivotsReady,IFERROR(GETPIVOTDATA("Churn Rate",'02_Pivots'!$A$52,"Tenure_Band","25-36 months","Contract","One Year"),""),0.07462686567164178) -> 0.074626866 | M22: =IF(nativePivotsReady,IFERROR(GETPIVOTDATA("Churn Rate",'02_Pivots'!$A$52,"Tenure_Band","25-36 months","Contract","Two Year"),""),0.015267175572519083) -> 0.015267176
E23: =IF(nativePivotsReady,IFERROR(GETPIVOTDATA("Existing Customers",'02_Pivots'!$A$52,"Tenure_Band","25-36 months","Contract","Month-to-Month"),""),433) -> 433 | I23: =IF(nativePivotsReady,IFERROR(GETPIVOTDATA("Existing Customers",'02_Pivots'!$A$52,"Tenure_Band","25-36 months","Contract","One Year"),""),268) -> 268 | M23: =IF(nativePivotsReady,IFERROR(GETPIVOTDATA("Existing Customers",'02_Pivots'!$A$52,"Tenure_Band","25-36 months","Contract","Two Year"),""),131) -> 131
A24: 37-48 months | E24: =IF(nativePivotsReady,IFERROR(GETPIVOTDATA("Churn Rate",'02_Pivots'!$A$52,"Tenure_Band","37-48 months","Contract","Month-to-Month"),""),0.375886524822695) -> 0.37588652 | I24: =IF(nativePivotsReady,IFERROR(GETPIVOTDATA("Churn Rate",'02_Pivots'!$A$52,"Tenure_Band","37-48 months","Contract","One Year"),""),0.12589928057553956) -> 0.12589928 | M24: =IF(nativePivotsReady,IFERROR(GETPIVOTDATA("Churn Rate",'02_Pivots'!$A$52,"Tenure_Band","37-48 months","Contract","Two Year"),""),0.019801980198019802) -> 0.01980198 | Q24: DSL | W24: 0.19973975
E25: =IF(nativePivotsReady,IFERROR(GETPIVOTDATA("Existing Customers",'02_Pivots'!$A$52,"Tenure_Band","37-48 months","Contract","Month-to-Month"),""),282) -> 282 | I25: =IF(nativePivotsReady,IFERROR(GETPIVOTDATA("Existing Customers",'02_Pivots'!$A$52,"Tenure_Band","37-48 months","Contract","One Year"),""),278) -> 278 | M25: =IF(nativePivotsReady,IFERROR(GETPIVOTDATA("Existing Customers",'02_Pivots'!$A$52,"Tenure_Band","37-48 months","Contract","Two Year"),""),202) -> 202
A26: 49-72 months | E26: =IF(nativePivotsReady,IFERROR(GETPIVOTDATA("Churn Rate",'02_Pivots'!$A$52,"Tenure_Band","49-72 months","Contract","Month-to-Month"),""),0.30067567567567566) -> 0.30067568 | I26: =IF(nativePivotsReady,IFERROR(GETPIVOTDATA("Churn Rate",'02_Pivots'!$A$52,"Tenure_Band","49-72 months","Contract","One Year"),""),0.12752721617418353) -> 0.12752722 | M26: =IF(nativePivotsReady,IFERROR(GETPIVOTDATA("Churn Rate",'02_Pivots'!$A$52,"Tenure_Band","49-72 months","Contract","Two Year"),""),0.03230769230769231) -> 0.032307692
E27: =IF(nativePivotsReady,IFERROR(GETPIVOTDATA("Existing Customers",'02_Pivots'!$A$52,"Tenure_Band","49-72 months","Contract","Month-to-Month"),""),296) -> 296 | I27: =IF(nativePivotsReady,IFERROR(GETPIVOTDATA("Existing Customers",'02_Pivots'!$A$52,"Tenure_Band","49-72 months","Contract","One Year"),""),643) -> 643 | M27: =IF(nativePivotsReady,IFERROR(GETPIVOTDATA("Existing Customers",'02_Pivots'!$A$52,"Tenure_Band","49-72 months","Contract","Two Year"),""),1300) -> 1300 | Q27: Internet customers only • association, not causation
A29: TOP 5 STATED CHURN REASONS | N29: DESCRIPTIVE CHURN RISK TIERS
A30: What churned customers most often said when leaving | N30: Where elevated churn and meaningful customer volume overlap
A31: BASELINE PREVIEW • NATIVE INTERACTIVITY ADDED BY VBA | N31: BASELINE PREVIEW • NATIVE INTERACTIVITY ADDED BY VBA
A32: Competitor had better devices | M32: 313 | N32: Very High | U32: 0.66512059 | V32: =IF(nativePivotsReady,IFERROR(GETPIVOTDATA("Existing Customers",'02_Pivots'!$F$38,"Descriptive_Churn_Risk_Tier","Very High"),0),2156) -> 2156
A33: Competitor made better offer | M33: 311 | N33: High | U33: 0.20651311 | V33: =IF(nativePivotsReady,IFERROR(GETPIVOTDATA("Existing Customers",'02_Pivots'!$F$38,"Descriptive_Churn_Risk_Tier","High"),0),1259) -> 1259
A34: Attitude of support person | M34: 220 | N34: Medium | U34: 0.072928821 | V34: =IF(nativePivotsReady,IFERROR(GETPIVOTDATA("Existing Customers",'02_Pivots'!$F$38,"Descriptive_Churn_Risk_Tier","Medium"),0),1714) -> 1714
A35: Don't know | M35: 130 | N35: Low | U35: 0.034246575 | V35: =IF(nativePivotsReady,IFERROR(GETPIVOTDATA("Existing Customers",'02_Pivots'!$F$38,"Descriptive_Churn_Risk_Tier","Low"),0),1460) -> 1460
A36: Competitor offered more data | M36: 117
A38: Self-reported exit reasons • not verified causes | N38: Rule-based descriptive tiers • not predictive probabilities
A40: EXECUTIVE INSIGHTS
A41: CRITICAL FINDING | G41: MAJOR DRIVER | M41: EARLY WARNING | S41: BUSINESS OPPORTUNITY
A42: =insightCritical -> Month-to-Month customers have a 51.7% churn rate, the highest contract-level exposure. | G42: =insightDriver -> Churn reaches 77.2% among customers in their first 0–6 months. | M42: =insightWarning -> Month-to-Month + 0–6 months + Fiber records 91.2% churn: 444 of 487 existing customers. | S42: =insightOpportunity -> Fiber churn is 42.1%; better devices (313) and better offers (311) lead stated exit reasons.
A43: Baseline executive context • insight cells are named for future dynamic narratives • associations and stated reasons do not establish causation
A45: BUSINESS RECOMMENDATIONS
A46: 01 EARLY-TENURE SAVE JOURNEY | I46: 02 COMMITMENT MIGRATION | Q46: 03 COMPETITOR VALUE RESPONSE
A48: Rationale | 0–6 month churn is 77.2%; the M2M + 0–6 + Fiber intersection reaches 91.2%. | I48: Rationale | Month-to-Month churn is 51.7%, the strongest contract-level exposure. | Q48: Rationale | Better devices (313) and better offers (311) lead stated reasons; Fiber churn is 42.1%.
A50: Action | Test onboarding check-ins, service recovery and targeted save treatment during the first 90 days. | I50: Action | Test transparent one- and two-year migration offers with clear customer value and safeguards. | Q50: Action | Review the device proposition and test competitive offers for relevant Fiber segments.
A53: EXPECTED IMPACT POTENTIAL • HIGH | I53: EXPECTED IMPACT POTENTIAL • HIGH | Q53: EXPECTED IMPACT POTENTIAL • MEDIUM–HIGH
...

Sheet 02_Pivots
A1: Native Pivot Support
A2: Create all six pivots by copying PT_KPI_Context so every slicer can share one PivotCache.
J4: PivotTable | K4: Destination | L4: Rows | M4: Columns | N4: Values | O4: Filters | P4: Dashboard object
J5: PT_KPI_Context | K5: A3 | L5: — | M5: — | N5: Sum Existing, Churned, Retained, MRVL | O5: — | P5: Six KPI cards
J6: PT_InternetType | K6: A12 | L6: Internet Type | M6: — | N6: Average Churn_Rate_Value | O6: Internet Service = Yes | P6: PC_InternetType
J7: PT_ChurnReasons | K7: A24 | L7: Churn Reason | M7: — | N7: Count Customer ID | O7: Status = Churned; Top 5 | P7: PC_ChurnReasons
J8: PT_RiskTier | K8: A38 | L8: Risk Tier | M8: — | N8: Average Churn_Rate_Value | O8: — | P8: PC_RiskTier
J9: PT_RiskTierVolume | K9: F38 | L9: Risk Tier | M9: — | N9: Sum Existing_Flag | O9: — | P9: Risk volume labels
J10: PT_ContractTenure | K10: A52 | L10: Tenure_Band | M10: Contract | N10: Average Churn Rate; Sum Existing | O10: — | P10: Heatmap
J13: Native Excel boundary
J14: Python intentionally does not create PivotTable, PivotChart, slicer, or report-connection XML. Use the exact Phase B runbook in EXCEL_DASHBOARD_BUILD_PLAN.md. Do not resave this workbook with openpyxl or XlsxWriter after native objects are added.

Sheet 03_Calculations
B1: Calculation & Validation Layer | H1: Native pivots ready?
B2: Current values become slicer-responsive when PT_KPI_Context is created in Excel Desktop. | H2: =NOT(ISERROR(GETPIVOTDATA("Existing Customers",'02_Pivots'!$A$3))) -> FALSE
B4: KPI | C4: Current | D4: Baseline | E4: Variance | F4: Status | H4: Helper-field audit
B5: Existing Customers | C5: =IFERROR(GETPIVOTDATA("Existing Customers",'02_Pivots'!$A$3),6589) -> 6589 | D5: 6589 | E5: =C5-D5 -> 0 | F5: =IF(ABS(E5)<0.0001,"PASS","FAIL") -> PASS | H5: Helper field | I5: Equivalent Excel logic
B6: Churned Customers | C6: =IFERROR(GETPIVOTDATA("Churned Customers",'02_Pivots'!$A$3),1869) -> 1869 | D6: 1869 | E6: =C6-D6 -> 0 | F6: =IF(ABS(E6)<0.0001,"PASS","FAIL") -> PASS | H6: Existing_Flag | I6: =--OR([@[Customer Status]]="Churned",[@[Customer Status]]="Stayed")
B7: Retained Customers | C7: =IFERROR(GETPIVOTDATA("Retained Customers",'02_Pivots'!$A$3),4720) -> 4720 | D7: 4720 | E7: =C7-D7 -> 0 | F7: =IF(ABS(E7)<0.0001,"PASS","FAIL") -> PASS | H7: Churn_Rate_Value | I7: =IF([@Existing_Flag]=1,[@Is_Churned],"")
B8: Churn Rate | C8: =IF(C5=0,NA(),C6/C5) -> 0.28365458 | D8: 0.28365458 | E8: =C8-D8 -> 0 | F8: =IF(ABS(E8)<0.0001,"PASS","FAIL") -> PASS | H8: Retention_Rate_Value | I8: =IF([@Existing_Flag]=1,[@Is_Retained],"")
B9: Retention Rate | C9: =IF(C5=0,NA(),C7/C5) -> 0.71634542 | D9: 0.71634542 | E9: =C9-D9 -> 0 | F9: =IF(ABS(E9)<0.0001,"PASS","FAIL") -> PASS | H9: MRVL_Row | I9: =IF([@Is_Churned]=1,[@[Monthly Charge]],0)
B10: Monthly Recurring Value Lost | C10: =IFERROR(GETPIVOTDATA("Monthly Recurring Value Lost",'02_Pivots'!$A$3),137086.65) -> 137086.65 | D10: 137086.65 | E10: =C10-D10 -> 0 | F10: =IF(ABS(E10)<0.0001,"PASS","FAIL") -> PASS | H10: Risk_Points | I10: M2M +3; 0-6 months +3; Fiber +2; no dependents +1; not married +1
H11: Risk Tier | I11: Very High >=6; High >=4; Medium >=2; otherwise Low
B13: Source & denominator QA
B14: Check | C14: Formula result | D14: Expected | E14: Status | H14: Native Excel checkpoint
B15: Total Customers | C15: =ROWS(tblCustomers[Customer ID]) -> 7043 | D15: 7043 | E15: =IF(ABS(C15-D15)<0.0001,"PASS","FAIL") -> PASS | H15: 1. Create PT_KPI_Context at 02_Pivots!A3 from tblCustomers.
B16: Joined Customers | C16: =COUNTIF(tblCustomers[Customer Status],"Joined") -> 454 | D16: 454 | E16: =IF(ABS(C16-D16)<0.0001,"PASS","FAIL") -> PASS | H16: 2. Copy it to A12, A24, A38, F38, and A52.
B17: Existing identity | C17: =SUM(tblCustomers[Existing_Flag]) -> 6589 | D17: 6589 | E17: =IF(ABS(C17-D17)<0.0001,"PASS","FAIL") -> PASS | H17: 3. Configure fields exactly as listed on 02_Pivots.
B18: Rate identity | C18: =SUM(tblCustomers[Is_Churned])/SUM(tblCustomers[Existing_Flag])+SUM(tblCustomers[Is_Retained])/SUM(tblCustomers[Existing_Flag]) -> 1 | D18: 1 | E18: =IF(ABS(C18-D18)<0.0001,"PASS","FAIL") -> PASS | H18: 4. Add three PivotCharts and place them in the prepared wells.
B19: High-risk intersection existing | C19: =COUNTIFS(tblCustomers[Contract],"Month-to-Month",tblCustomers[Tenure_Band],"0-6 months",tblCustomers[Internet Type],"Fiber Optic",tblCustomers[Existing_Flag],1) -> 487 | D19: 487 | E19: =IF(ABS(C19-D19)<0.0001,"PASS","FAIL") -> PASS | H19: 5. Add Contract, Tenure_Band_Slicer, and Internet Type slicers.
B20: High-risk intersection churned | C20: =COUNTIFS(tblCustomers[Contract],"Month-to-Month",tblCustomers[Tenure_Band],"0-6 months",tblCustomers[Internet Type],"Fiber Optic",tblCustomers[Is_Churned],1) -> 444 | D20: 444 | E20: =IF(ABS(C20-D20)<0.0001,"PASS","FAIL") -> PASS | H20: 6. Connect each slicer to all six PivotTables.
H21: 7. Refresh All, recalculate, validate, then hide support sheets.
H24: Named insight | I24: Baseline executive context
H25: insightCritical | I25: Month-to-Month customers have a 51.7% churn rate, the highest contract-level exposure.
H26: insightDriver | I26: Churn reaches 77.2% among customers in their first 0–6 months.
H27: insightWarning | I27: Month-to-Month + 0–6 months + Fiber records 91.2% churn: 444 of 487 existing customers.
H28: insightOpportunity | I28: Fiber churn is 42.1%; better devices (313) and better offers (311) lead stated exit reasons.

Sheet 04_Data
A1: Customer ID | B1: Gender | C1: Age | D1: Married | E1: Number of Dependents | F1: City | G1: Zip Code | H1: Latitude | I1: Longitude | J1: Number of Referrals | K1: Tenure in Months | L1: Offer | M1: Phone Service | N1: Avg Monthly Long Distance Charges | O1: Multiple Lines | P1: Internet Service | Q1: Internet Type | R1: Avg Monthly GB Download | S1: Online Security | T1: Online Backup | U1: Device Protection Plan | V1: Premium Tech Support | W1: Streaming TV | X1: Streaming Movies | Y1: Streaming Music | Z1: Unlimited Data | AA1: Contract | AB1: Paperless Billing | AC1: Payment Method | AD1: Monthly Charge | AE1: Total Charges | AF1: Total Refunds | AG1: Total Extra Data Charges | AH1: Total Long Distance Charges | AI1: Total Revenue | AJ1: Customer Status | AK1: Churn Category | AL1: Churn Reason | AM1: Is_Churned | AN1: Is_Retained | AO1: Flag_Negative_Monthly_Charge | AP1: Tenure_Band | AQ1: Age_Band | AR1: Charge_Band | AS1: Add_On_Count | AT1: Zip_Population | AU1: Existing_Flag | AV1: Churn_Rate_Value | AW1: Retention_Rate_Value | AX1: MRVL_Row | AY1: Tenure_Band_Sort | AZ1: Tenure_Band_Slicer | BA1: Risk_Points | BB1: Descriptive_Churn_Risk_Tier | BC1: Risk_Tier_Sort
A2: 0002-ORFBO | B2: Female | C2: 37 | D2: Yes | E2: 0 | F2: Frazier Park | G2: 93225 | H2: 34.827662 | I2: -118.99907 | J2: 2 | K2: 9 | L2: None | M2: Yes | N2: 42.39 | O2: No | P2: Yes | Q2: Cable | R2: 16.0 | S2: No | T2: Yes | U2: No | V2: Yes | W2: Yes | X2: No | Y2: No | Z2: Yes | AA2: One Year | AB2: Yes | AC2: Credit Card | AD2: 65.6 | AE2: 593.3 | AF2: 0 | AG2: 0 | AH2: 381.51 | AI2: 974.81 | AJ2: Stayed | AM2: 0 | AN2: 1 | AO2: 0 | AP2: 7-12 months | AQ2: 30-39 | AR2: $50-69 | AS2: 4 | AT2: 4498 | AU2: 1 | AV2: 0 | AW2: 1 | AX2: 0 | AY2: 2 | AZ2: 02 | 7-12 months | BA2: 1 | BB2: Low | BC2: 4
A3: 0003-MKNFE | B3: Male | C3: 46 | D3: No | E3: 0 | F3: Glendale | G3: 91206 | H3: 34.162515 | I3: -118.20387 | J3: 0 | K3: 9 | L3: None | M3: Yes | N3: 10.69 | O3: Yes | P3: Yes | Q3: Cable | R3: 10.0 | S3: No | T3: No | U3: No | V3: No | W3: No | X3: Yes | Y3: Yes | Z3: No | AA3: Month-to-Month | AB3: No | AC3: Credit Card | AD3: -4 | AE3: 542.4 | AF3: 38.33 | AG3: 10 | AH3: 96.21 | AI3: 610.28 | AJ3: Stayed | AM3: 0 | AN3: 1 | AO3: 1 | AP3: 7-12 months | AQ3: 40-49 | AR3: Credit (<$0) | AS3: 2 | AT3: 31297 | AU3: 1 | AV3: 0 | AW3: 1 | AX3: 0 | AY3: 2 | AZ3: 02 | 7-12 months | BA3: 5 | BB3: High | BC3: 2
A4: 0004-TLHLJ | B4: Male | C4: 50 | D4: No | E4: 0 | F4: Costa Mesa | G4: 92627 | H4: 33.645672 | I4: -117.92261 | J4: 0 | K4: 4 | L4: Offer E | M4: Yes | N4: 33.65 | O4: No | P4: Yes | Q4: Fiber Optic | R4: 30.0 | S4: No | T4: No | U4: Yes | V4: No | W4: No | X4: No | Y4: No | Z4: Yes | AA4: Month-to-Month | AB4: Yes | AC4: Bank Withdrawal | AD4: 73.9 | AE4: 280.85 | AF4: 0 | AG4: 0 | AH4: 134.6 | AI4: 415.45 | AJ4: Churned | AK4: Competitor | AL4: Competitor had better devices | AM4: 1 | AN4: 0 | AO4: 0 | AP4: 0-6 months | AQ4: 50-59 | AR4: $70-89 | AS4: 2 | AT4: 62069 | AU4: 1 | AV4: 1 | AW4: 0 | AX4: 73.9 | AY4: 1 | AZ4: 01 | 0-6 months | BA4: 10 | BB4: Very High | BC4: 1
A5: 0011-IGKFF | B5: Male | C5: 78 | D5: Yes | E5: 0 | F5: Martinez | G5: 94553 | H5: 38.014457 | I5: -122.11543 | J5: 1 | K5: 13 | L5: Offer D | M5: Yes | N5: 27.82 | O5: No | P5: Yes | Q5: Fiber Optic | R5: 4.0 | S5: No | T5: Yes | U5: Yes | V5: No | W5: Yes | X5: Yes | Y5: No | Z5: Yes | AA5: Month-to-Month | AB5: Yes | AC5: Bank Withdrawal | AD5: 98 | AE5: 1237.85 | AF5: 0 | AG5: 0 | AH5: 361.66 | AI5: 1599.51 | AJ5: Churned | AK5: Dissatisfaction | AL5: Product dissatisfaction | AM5: 1 | AN5: 0 | AO5: 0 | AP5: 13-24 months | AQ5: 70+ | AR5: $90+ | AS5: 5 | AT5: 46677 | AU5: 1 | AV5: 1 | AW5: 0 | AX5: 98 | AY5: 3 | AZ5: 03 | 13-24 months | BA5: 6 | BB5: Very High | BC5: 1
A6: 0013-EXCHZ | B6: Female | C6: 75 | D6: Yes | E6: 0 | F6: Camarillo | G6: 93010 | H6: 34.227846 | I6: -119.0799 | J6: 3 | K6: 3 | L6: None | M6: Yes | N6: 7.38 | O6: No | P6: Yes | Q6: Fiber Optic | R6: 11.0 | S6: No | T6: No | U6: No | V6: Yes | W6: Yes | X6: No | Y6: No | Z6: Yes | AA6: Month-to-Month | AB6: Yes | AC6: Credit Card | AD6: 83.9 | AE6: 267.4 | AF6: 0 | AG6: 0 | AH6: 22.14 | AI6: 289.54 | AJ6: Churned | AK6: Dissatisfaction | AL6: Network reliability | AM6: 1 | AN6: 0 | AO6: 0 | AP6: 0-6 months | AQ6: 70+ | AR6: $70-89 | AS6: 3 | AT6: 42853 | AU6: 1 | AV6: 1 | AW6: 0 | AX6: 83.9 | AY6: 1 | AZ6: 01 | 0-6 months | BA6: 9 | BB6: Very High | BC6: 1
A7: 0013-MHZWF | B7: Female | C7: 23 | D7: No | E7: 3 | F7: Midpines | G7: 95345 | H7: 37.581496 | I7: -119.97276 | J7: 0 | K7: 9 | L7: Offer E | M7: Yes | N7: 16.77 | O7: No | P7: Yes | Q7: Cable | R7: 73.0 | S7: No | T7: No | U7: No | V7: Yes | W7: Yes | X7: Yes | Y7: Yes | Z7: Yes | AA7: Month-to-Month | AB7: Yes | AC7: Credit Card | AD7: 69.4 | AE7: 571.45 | AF7: 0 | AG7: 0 | AH7: 150.93 | AI7: 722.38 | AJ7: Stayed | AM7: 0 | AN7: 1 | AO7: 0 | AP7: 7-12 months | AQ7: Under 30 | AR7: $50-69 | AS7: 5 | AT7: 433 | AU7: 1 | AV7: 0 | AW7: 1 | AX7: 0 | AY7: 2 | AZ7: 02 | 7-12 months | BA7: 4 | BB7: High | BC7: 2
A8: 0013-SMEOE | B8: Female | C8: 67 | D8: Yes | E8: 0 | F8: Lompoc | G8: 93437 | H8: 34.757477 | I8: -120.55051 | J8: 1 | K8: 71 | L8: Offer A | M8: Yes | N8: 9.96 | O8: No | P8: Yes | Q8: Fiber Optic | R8: 14.0 | S8: Yes | T8: Yes | U8: Yes | V8: Yes | W8: Yes | X8: Yes | Y8: Yes | Z8: Yes | AA8: Two Year | AB8: Yes | AC8: Bank Withdrawal | AD8: 109.7 | AE8: 7904.25 | AF8: 0 | AG8: 0 | AH8: 707.16 | AI8: 8611.41 | AJ8: Stayed | AM8: 0 | AN8: 1 | AO8: 0 | AP8: 49-72 months | AQ8: 60-69 | AR8: $90+ | AS8: 8 | AT8: 6165 | AU8: 1 | AV8: 0 | AW8: 1 | AX8: 0 | AY8: 6 | AZ8: 06 | 49-72 months | BA8: 3 | BB8: Medium | BC8: 3
A9: 0014-BMAQU | B9: Male | C9: 52 | D9: Yes | E9: 0 | F9: Napa | G9: 94558 | H9: 38.489789 | I9: -122.27011 | J9: 8 | K9: 63 | L9: Offer B | M9: Yes | N9: 12.96 | O9: Yes | P9: Yes | Q9: Fiber Optic | R9: 7.0 | S9: Yes | T9: No | U9: No | V9: Yes | W9: No | X9: No | Y9: No | Z9: No | AA9: Two Year | AB9: Yes | AC9: Credit Card | AD9: 84.65 | AE9: 5377.8 | AF9: 0 | AG9: 20 | AH9: 816.48 | AI9: 6214.28 | AJ9: Stayed | AM9: 0 | AN9: 1 | AO9: 0 | AP9: 49-72 months | AQ9: 50-59 | AR9: $70-89 | AS9: 2 | AT9: 63947 | AU9: 1 | AV9: 0 | AW9: 1 | AX9: 0 | AY9: 6 | AZ9: 06 | 49-72 months | BA9: 3 | BB9: Medium | BC9: 3
A10: 0015-UOCOJ | B10: Female | C10: 68 | D10: No | E10: 0 | F10: Simi Valley | G10: 93063 | H10: 34.296813 | I10: -118.6857 | J10: 0 | K10: 7 | L10: Offer E | M10: Yes | N10: 10.53 | O10: No | P10: Yes | Q10: DSL | R10: 21.0 | S10: Yes | T10: No | U10: No | V10: No | W10: No | X10: No | Y10: No | Z10: Yes | AA10: Two Year | AB10: Yes | AC10: Bank Withdrawal | AD10: 48.2 | AE10: 340.35 | AF10: 0 | AG10: 0 | AH10: 73.71 | AI10: 414.06 | AJ10: Stayed | AM10: 0 | AN10: 1 | AO10: 0 | AP10: 7-12 months | AQ10: 60-69 | AR10: $30-49 | AS10: 2 | AT10: 49027 | AU10: 1 | AV10: 0 | AW10: 1 | AX10: 0 | AY10: 2 | AZ10: 02 | 7-12 months | BA10: 2 | BB10: Medium | BC10: 3
A11: 0016-QLJIS | B11: Female | C11: 43 | D11: Yes | E11: 1 | F11: Sheridan | G11: 95681 | H11: 38.984756 | I11: -121.34507 | J11: 3 | K11: 65 | L11: None | M11: Yes | N11: 28.46 | O11: Yes | P11: Yes | Q11: Cable | R11: 14.0 | S11: Yes | T11: Yes | U11: Yes | V11: Yes | W11: Yes | X11: Yes | Y11: Yes | Z11: Yes | AA11: Two Year | AB11: Yes | AC11: Credit Card | AD11: 90.45 | AE11: 5957.9 | AF11: 0 | AG11: 0 | AH11: 1849.9 | AI11: 7807.8 | AJ11: Stayed | AM11: 0 | AN11: 1 | AO11: 0 | AP11: 49-72 months | AQ11: 40-49 | AR11: $90+ | AS11: 8 | AT11: 1219 | AU11: 1 | AV11: 0 | AW11: 1 | AX11: 0 | AY11: 6 | AZ11: 06 | 49-72 months | BA11: 0 | BB11: Low | BC11: 4
A12: 0017-DINOC | B12: Male | C12: 47 | D12: No | E12: 0 | F12: Rancho Santa Fe | G12: 92091 | H12: 32.99356 | I12: -117.20712 | J12: 0 | K12: 54 | L12: None | M12: No | N12: N/A | O12: N/A | P12: Yes | Q12: Cable | R12: 10.0 | S12: Yes | T12: No | U12: No | V12: Yes | W12: Yes | X12: No | Y12: No | Z12: Yes | AA12: Two Year | AB12: No | AC12: Credit Card | AD12: 45.2 | AE12: 2460.55 | AF12: 0 | AG12: 0 | AH12: 0 | AI12: 2460.55 | AJ12: Stayed | AM12: 0 | AN12: 1 | AO12: 0 | AP12: 49-72 months | AQ12: 40-49 | AR12: $30-49 | AS12: 4 | AT12: 1072 | AU12: 1 | AV12: 0 | AW12: 1 | AX12: 0 | AY12: 6 | AZ12: 06 | 49-72 months | BA12: 2 | BB12: Medium | BC12: 3
A13: 0017-IUDMW | B13: Female | C13: 25 | D13: Yes | E13: 2 | F13: Sunnyvale | G13: 94086 | H13: 37.378541 | I13: -122.02046 | J13: 2 | K13: 72 | L13: None | M13: Yes | N13: 16.01 | O13: Yes | P13: Yes | Q13: Fiber Optic | R13: 59.0 | S13: Yes | T13: Yes | U13: Yes | V13: Yes | W13: Yes | X13: Yes | Y13: Yes | Z13: Yes | AA13: Two Year | AB13: Yes | AC13: Credit Card | AD13: 116.8 | AE13: 8456.75 | AF13: 0 | AG13: 0 | AH13: 1152.72 | AI13: 9609.47 | AJ13: Stayed | AM13: 0 | AN13: 1 | AO13: 0 | AP13: 49-72 months | AQ13: Under 30 | AR13: $90+ | AS13: 8 | AT13: 64010 | AU13: 1 | AV13: 0 | AW13: 1 | AX13: 0 | AY13: 6 | AZ13: 06 | 49-72 months | BA13: 2 | BB13: Medium | BC13: 3
A14: 0018-NYROU | B14: Female | C14: 58 | D14: Yes | E14: 0 | F14: Antelope | G14: 95843 | H14: 38.715498 | I14: -121.36341 | J14: 0 | K14: 5 | L14: None | M14: Yes | N14: 18.65 | O14: No | P14: Yes | Q14: Fiber Optic | R14: 10.0 | S14: No | T14: No | U14: No | V14: No | W14: No | X14: No | Y14: No | Z14: Yes | AA14: Month-to-Month | AB14: Yes | AC14: Bank Withdrawal | AD14: 68.95 | AE14: 351.5 | AF14: 0 | AG14: 0 | AH14: 93.25 | AI14: 444.75 | AJ14: Stayed | AM14: 0 | AN14: 1 | AO14: 0 | AP14: 0-6 months | AQ14: 50-59 | AR14: $50-69 | AS14: 1 | AT14: 36432 | AU14: 1 | AV14: 0 | AW14: 1 | AX14: 0 | AY14: 1 | AZ14: 01 | 0-6 months | BA14: 9 | BB14: Very High | BC14: 1
A15: 0019-EFAEP | B15: Female | C15: 32 | D15: No | E15: 0 | F15: La Mesa | G15: 91942 | H15: 32.782501 | I15: -117.01611 | J15: 0 | K15: 72 | L15: Offer A | M15: Yes | N15: 2.25 | O15: Yes | P15: Yes | Q15: Fiber Optic | R15: 16.0 | S15: Yes | T15: Yes | U15: Yes | V15: No | W15: Yes | X15: No | Y15: No | Z15: Yes | AA15: Two Year | AB15: Yes | AC15: Bank Withdrawal | AD15: 101.3 | AE15: 7261.25 | AF15: 0 | AG15: 0 | AH15: 162 | AI15: 7423.25 | AJ15: Stayed | AM15: 0 | AN15: 1 | AO15: 0 | AP15: 49-72 months | AQ15: 30-39 | AR15: $90+ | AS15: 5 | AT15: 24005 | AU15: 1 | AV15: 0 | AW15: 1 | AX15: 0 | AY15: 6 | AZ15: 06 | 49-72 months | BA15: 4 | BB15: High | BC15: 2
A16: 0019-GFNTW | B16: Female | C16: 39 | D16: No | E16: 0 | F16: Los Olivos | G16: 93441 | H16: 34.70434 | I16: -120.02609 | J16: 0 | K16: 56 | L16: None | M16: No | N16: N/A | O16: N/A | P16: Yes | Q16: DSL | R16: 19.0 | S16: Yes | T16: Yes | U16: Yes | V16: Yes | W16: No | X16: No | Y16: No | Z16: Yes | AA16: Two Year | AB16: No | AC16: Bank Withdrawal | AD16: 45.05 | AE16: 2560.1 | AF16: 0 | AG16: 0 | AH16: 0 | AI16: 2560.1 | AJ16: Stayed | AM16: 0 | AN16: 1 | AO16: 0 | AP16: 49-72 months | AQ16: 30-39 | AR16: $30-49 | AS16: 5 | AT16: 1317 | AU16: 1 | AV16: 0 | AW16: 1 | AX16: 0 | AY16: 6 | AZ16: 06 | 49-72 months | BA16: 2 | BB16: Medium | BC16: 3
A17: 0020-INWCK | B17: Female | C17: 58 | D17: Yes | E17: 2 | F17: Woodlake | G17: 93286 | H17: 36.464635 | I17: -119.09435 | J17: 9 | K17: 71 | L17: Offer A | M17: Yes | N17: 27.26 | O17: Yes | P17: Yes | Q17: Fiber Optic | R17: 12.0 | S17: No | T17: Yes | U17: Yes | V17: No | W17: No | X17: Yes | Y17: Yes | Z17: Yes | AA17: Two Year | AB17: Yes | AC17: Credit Card | AD17: 95.75 | AE17: 6849.4 | AF17: 0 | AG17: 0 | AH17: 1935.46 | AI17: 8784.86 | AJ17: Stayed | AM17: 0 | AN17: 1 | AO17: 0 | AP17: 49-72 months | AQ17: 50-59 | AR17: $90+ | AS17: 5 | AT17: 8870 | AU17: 1 | AV17: 0 | AW17: 1 | AX17: 0 | AY17: 6 | AZ17: 06 | 49-72 months | BA17: 2 | BB17: Medium | BC17: 3
A18: 0020-JDNXP | B18: Female | C18: 52 | D18: Yes | E18: 1 | F18: Point Reyes Station | G18: 94956 | H18: 38.060264 | I18: -122.83065 | J18: 0 | K18: 34 | L18: None | M18: No | N18: N/A | O18: N/A | P18: Yes | Q18: DSL | R18: 20.0 | S18: Yes | T18: No | U18: Yes | V18: Yes | W18: Yes | X18: Yes | Y18: Yes | Z18: Yes | AA18: One Year | AB18: No | AC18: Credit Card | AD18: 61.25 | AE18: 1993.2 | AF18: 0 | AG18: 0 | AH18: 0 | AI18: 1993.2 | AJ18: Stayed | AM18: 0 | AN18: 1 | AO18: 0 | AP18: 25-36 months | AQ18: 50-59 | AR18: $50-69 | AS18: 7 | AT18: 1885 | AU18: 1 | AV18: 0 | AW18: 1 | AX18: 0 | AY18: 4 | AZ18: 04 | 25-36 months | BA18: 0 | BB18: Low | BC18: 4
A19: 0021-IKXGC | B19: Female | C19: 72 | D19: No | E19: 0 | F19: San Marcos | G19: 92078 | H19: 33.119028 | I19: -117.16604 | J19: 0 | K19: 1 | L19: Offer E | M19: Yes | N19: 7.77 | O19: Yes | P19: Yes | Q19: Fiber Optic | R19: 22.0 | S19: No | T19: No | U19: No | V19: No | W19: No | X19: No | Y19: No | Z19: Yes | AA19: One Year | AB19: Yes | AC19: Bank Withdrawal | AD19: 72.1 | AE19: 72.1 | AF19: 0 | AG19: 0 | AH19: 7.77 | AI19: 79.87 | AJ19: Joined | AM19: 0 | AN19: 0 | AO19: 0 | AP19: 0-6 months | AQ19: 70+ | AR19: $70-89 | AS19: 1 | AT19: 6760 | AU19: 0 | AX19: 0 | AY19: 1 | AZ19: 01 | 0-6 months | BA19: 7 | BB19: Very High | BC19: 1
A20: 0022-TCJCI | B20: Male | C20: 79 | D20: No | E20: 0 | F20: Daly City | G20: 94015 | H20: 37.680844 | I20: -122.48131 | J20: 0 | K20: 45 | L20: None | M20: Yes | N20: 10.67 | O20: No | P20: Yes | Q20: DSL | R20: 17.0 | S20: Yes | T20: No | U20: Yes | V20: No | W20: No | X20: Yes | Y20: No | Z20: Yes | AA20: One Year | AB20: No | AC20: Credit Card | AD20: 62.7 | AE20: 2791.5 | AF20: 0 | AG20: 0 | AH20: 480.15 | AI20: 3271.65 | AJ20: Churned | AK20: Dissatisfaction | AL20: Limited range of services | AM20: 1 | AN20: 0 | AO20: 0 | AP20: 37-48 months | AQ20: 70+ | AR20: $50-69 | AS20: 4 | AT20: 63337 | AU20: 1 | AV20: 1 | AW20: 0 | AX20: 62.7 | AY20: 5 | AZ20: 05 | 37-48 months | BA20: 2 | BB20: Medium | BC20: 3
A21: 0023-HGHWL | B21: Male | C21: 67 | D21: No | E21: 0 | F21: Morgan Hill | G21: 95037 | H21: 37.161544 | I21: -121.64937 | J21: 0 | K21: 1 | L21: None | M21: No | N21: N/A | O21: N/A | P21: Yes | Q21: Cable | R21: 9.0 | S21: No | T21: No | U21: No | V21: No | W21: No | X21: No | Y21: No | Z21: Yes | AA21: Month-to-Month | AB21: Yes | AC21: Bank Withdrawal | AD21: 25.1 | AE21: 25.1 | AF21: 0 | AG21: 0 | AH21: 0 | AI21: 25.1 | AJ21: Churned | AK21: Competitor | AL21: Competitor made better offer | AM21: 1 | AN21: 0 | AO21: 0 | AP21: 0-6 months | AQ21: 60-69 | AR21: Low (<$30) | AS21: 1 | AT21: 41707 | AU21: 1 | AV21: 1 | AW21: 0 | AX21: 25.1 | AY21: 1 | AZ21: 01 | 0-6 months | BA21: 8 | BB21: Very High | BC21: 1
A22: 0023-UYUPN | B22: Female | C22: 79 | D22: Yes | E22: 0 | F22: Ahwahnee | G22: 93601 | H22: 37.375816 | I22: -119.73994 | J22: 0 | K22: 50 | L22: None | M22: Yes | N22: 31.43 | O22: Yes | P22: No | Q22: N/A | R22: N/A | S22: N/A | T22: N/A | U22: N/A | V22: N/A | W22: N/A | X22: N/A | Y22: N/A | Z22: N/A | AA22: One Year | AB22: No | AC22: Bank Withdrawal | AD22: 25.2 | AE22: 1306.3 | AF22: 0 | AG22: 0 | AH22: 1571.5 | AI22: 2877.8 | AJ22: Stayed | AM22: 0 | AN22: 1 | AO22: 0 | AP22: 49-72 months | AQ22: 70+ | AR22: Low (<$30) | AT22: 1968 | AU22: 1 | AV22: 0 | AW22: 1 | AX22: 0 | AY22: 6 | AZ22: 06 | 49-72 months | BA22: 1 | BB22: Low | BC22: 4
A23: 0023-XUOPT | B23: Female | C23: 26 | D23: Yes | E23: 0 | F23: Carnelian Bay | G23: 96140 | H23: 39.227434 | I23: -120.09181 | J23: 1 | K23: 13 | L23: None | M23: Yes | N23: 43.56 | O23: Yes | P23: Yes | Q23: Fiber Optic | R23: 52.0 | S23: No | T23: Yes | U23: Yes | V23: No | W23: Yes | X23: No | Y23: No | Z23: Yes | AA23: Month-to-Month | AB23: No | AC23: Bank Withdrawal | AD23: 94.1 | AE23: 1215.6 | AF23: 0 | AG23: 0 | AH23: 566.28 | AI23: 1781.88 | AJ23: Churned | AK23: Other | AL23: Don't know | AM23: 1 | AN23: 0 | AO23: 0 | AP23: 13-24 months | AQ23: Under 30 | AR23: $90+ | AS23: 4 | AT23: 1943 | AU23: 1 | AV23: 1 | AW23: 0 | AX23: 94.1 | AY23: 3 | AZ23: 03 | 13-24 months | BA23: 6 | BB23: Very High | BC23: 1
A24: 0027-KWYKW | B24: Female | C24: 30 | D24: Yes | E24: 2 | F24: Alpaugh | G24: 93201 | H24: 35.869626 | I24: -119.49877 | J24: 1 | K24: 23 | L24: Offer D | M24: Yes | N24: 34.91 | O24: Yes | P24: Yes | Q24: Fiber Optic | R24: 30.0 | S24: No | T24: No | U24: No | V24: No | W24: Yes | X24: No | Y24: No | Z24: Yes | AA24: Month-to-Month | AB24: Yes | AC24: Bank Withdrawal | AD24: 83.75 | AE24: 1849.95 | AF24: 0 | AG24: 0 | AH24: 802.93 | AI24: 2652.88 | AJ24: Stayed | AM24: 0 | AN24: 1 | AO24: 0 | AP24: 13-24 months | AQ24: 30-39 | AR24: $70-89 | AS24: 2 | AT24: 1054 | AU24: 1 | AV24: 0 | AW24: 1 | AX24: 0 | AY24: 3 | AZ24: 03 | 13-24 months | BA24: 5 | BB24: High | BC24: 2
A25: 0030-FNXPP | B25: Female | C25: 22 | D25: No | E25: 0 | F25: Keeler | G25: 93530 | H25: 36.560498 | I25: -117.96246 | J25: 0 | K25: 3 | L25: None | M25: Yes | N25: 3.12 | O25: No | P25: No | Q25: N/A | R25: N/A | S25: N/A | T25: N/A | U25: N/A | V25: N/A | W25: N/A | X25: N/A | Y25: N/A | Z25: N/A | AA25: Month-to-Month | AB25: No | AC25: Credit Card | AD25: 19.85 | AE25: 57.2 | AF25: 0 | AG25: 0 | AH25: 9.36 | AI25: 66.56 | AJ25: Joined | AM25: 0 | AN25: 0 | AO25: 0 | AP25: 0-6 months | AQ25: Under 30 | AR25: Low (<$30) | AT25: 71 | AU25: 0 | AX25: 0 | AY25: 1 | AZ25: 01 | 0-6 months | BA25: 8 | BB25: Very High | BC25: 1
A26: 0031-PVLZI | B26: Female | C26: 34 | D26: Yes | E26: 0 | F26: Korbel | G26: 95550 | H26: 40.7666 | I26: -123.80458 | J26: 0 | K26: 4 | L26: Offer E | M26: Yes | N26: 12.43 | O26: No | P26: No | Q26: N/A | R26: N/A | S26: N/A | T26: N/A | U26: N/A | V26: N/A | W26: N/A | X26: N/A | Y26: N/A | Z26: N/A | AA26: Month-to-Month | AB26: No | AC26: Credit Card | AD26: 20.35 | AE26: 76.35 | AF26: 0 | AG26: 0 | AH26: 49.72 | AI26: 126.07 | AJ26: Churned | AK26: Price | AL26: Long distance charges | AM26: 1 | AN26: 0 | AO26: 0 | AP26: 0-6 months | AQ26: 30-39 | AR26: Low (<$30) | AT26: 155 | AU26: 1 | AV26: 1 | AW26: 0 | AX26: 20.35 | AY26: 1 | AZ26: 01 | 0-6 months | BA26: 7 | BB26: Very High | BC26: 1
A27: 0032-PGELS | B27: Female | C27: 37 | D27: Yes | E27: 1 | F27: Palomar Mountain | G27: 92060 | H27: 33.309852 | I27: -116.82309 | J27: 1 | K27: 1 | L27: None | M27: No | N27: N/A | O27: N/A | P27: Yes | Q27: DSL | R27: 19.0 | S27: Yes | T27: No | U27: No | V27: No | W27: No | X27: No | Y27: No | Z27: Yes | AA27: Month-to-Month | AB27: No | AC27: Bank Withdrawal | AD27: 30.5 | AE27: 30.5 | AF27: 0 | AG27: 0 | AH27: 0 | AI27: 30.5 | AJ27: Churned | AK27: Attitude | AL27: Attitude of service provider | AM27: 1 | AN27: 0 | AO27: 0 | AP27: 0-6 months | AQ27: 30-39 | AR27: $30-49 | AS27: 2 | AT27: 234 | AU27: 1 | AV27: 1 | AW27: 0 | AX27: 30.5 | AY27: 1 | AZ27: 01 | 0-6 months | BA27: 6 | BB27: Very High | BC27: 1
A28: 0036-IHMOT | B28: Female | C28: 37 | D28: Yes | E28: 3 | F28: Parlier | G28: 93648 | H28: 36.622237 | I28: -119.52113 | J28: 10 | K28: 55 | L28: None | M28: Yes | N28: 35.04 | O28: No | P28: Yes | Q28: Fiber Optic | R28: 57.0 | S28: No | T28: Yes | U28: Yes | V28: Yes | W28: Yes | X28: Yes | Y28: Yes | Z28: No | AA28: One Year | AB28: Yes | AC28: Bank Withdrawal | AD28: 103.7 | AE28: 5656.75 | AF28: 0 | AG28: 20 | AH28: 1927.2 | AI28: 7603.95 | AJ28: Stayed | AM28: 0 | AN28: 1 | AO28: 0 | AP28: 49-72 months | AQ28: 30-39 | AR28: $90+ | AS28: 6 | AT28: 12587 | AU28: 1 | AV28: 0 | AW28: 1 | AX28: 0 | AY28: 6 | AZ28: 06 | 49-72 months | BA28: 2 | BB28: Medium | BC28: 3
A29: 0040-HALCW | B29: Male | C29: 42 | D29: Yes | E29: 3 | F29: Modesto | G29: 95358 | H29: 37.612612 | I29: -121.10857 | J29: 3 | K29: 54 | L29: None | M29: Yes | N29: 19.7 | O29: No | P29: No | Q29: N/A | R29: N/A | S29: N/A | T29: N/A | U29: N/A | V29: N/A | W29: N/A | X29: N/A | Y29: N/A | Z29: N/A | AA29: Two Year | AB29: No | AC29: Credit Card | AD29: 20.4 | AE29: 1090.6 | AF29: 0 | AG29: 0 | AH29: 1063.8 | AI29: 2154.4 | AJ29: Stayed | AM29: 0 | AN29: 1 | AO29: 0 | AP29: 49-72 months | AQ29: 40-49 | AR29: Low (<$30) | AT29: 30668 | AU29: 1 | AV29: 0 | AW29: 1 | AX29: 0 | AY29: 6 | AZ29: 06 | 49-72 months | BA29: 0 | BB29: Low | BC29: 4
A30: 0042-JVWOJ | B30: Male | C30: 64 | D30: No | E30: 0 | F30: Glen Ellen | G30: 95442 | H30: 38.368744 | I30: -122.52264 | J30: 0 | K30: 26 | L30: Offer C | M30: Yes | N30: 37.7 | O30: No | P30: No | Q30: N/A | R30: N/A | S30: N/A | T30: N/A | U30: N/A | V30: N/A | W30: N/A | X30: N/A | Y30: N/A | Z30: N/A | AA30: One Year | AB30: Yes | AC30: Bank Withdrawal | AD30: 19.6 | AE30: 471.85 | AF30: 21.25 | AG30: 0 | AH30: 980.2 | AI30: 1430.8 | AJ30: Stayed | AM30: 0 | AN30: 1 | AO30: 0 | AP30: 25-36 months | AQ30: 60-69 | AR30: Low (<$30) | AT30: 4101 | AU30: 1 | AV30: 0 | AW30: 1 | AX30: 0 | AY30: 4 | AZ30: 04 | 25-36 months | BA30: 2 | BB30: Medium | BC30: 3
A31: 0042-RLHYP | B31: Female | C31: 47 | D31: Yes | E31: 3 | F31: Eureka | G31: 95503 | H31: 40.737431 | I31: -124.1089 | J31: 5 | K31: 69 | L31: None | M31: Yes | N31: 38.39 | O31: No | P31: No | Q31: N/A | R31: N/A | S31: N/A | T31: N/A | U31: N/A | V31: N/A | W31: N/A | X31: N/A | Y31: N/A | Z31: N/A | AA31: Two Year | AB31: No | AC31: Bank Withdrawal | AD31: 19.7 | AE31: 1396.9 | AF31: 0 | AG31: 0 | AH31: 2648.91 | AI31: 4045.81 | AJ31: Stayed | AM31: 0 | AN31: 1 | AO31: 0 | AP31: 49-72 months | AQ31: 40-49 | AR31: Low (<$30) | AT31: 23570 | AU31: 1 | AV31: 0 | AW31: 1 | AX31: 0 | AY31: 6 | AZ31: 06 | 49-72 months | BA31: 0 | BB31: Low | BC31: 4
A32: 0048-LUMLS | B32: Male | C32: 23 | D32: Yes | E32: 3 | F32: Moss Beach | G32: 94038 | H32: 37.515556 | I32: -122.50231 | J32: 1 | K32: 37 | L32: Offer C | M32: Yes | N32: 43.01 | O32: No | P32: Yes | Q32: Fiber Optic | R32: 51.0 | S32: No | T32: No | U32: No | V32: No | W32: Yes | X32: Yes | Y32: Yes | Z32: Yes | AA32: One Year | AB32: No | AC32: Credit Card | AD32: 91.2 | AE32: 3247.55 | AF32: 0 | AG32: 0 | AH32: 1591.37 | AI32: 4838.92 | AJ32: Stayed | AM32: 0 | AN32: 1 | AO32: 0 | AP32: 37-48 months | AQ32: Under 30 | AR32: $90+ | AS32: 4 | AT32: 3064 | AU32: 1 | AV32: 0 | AW32: 1 | AX32: 0 | AY32: 5 | AZ32: 05 | 37-48 months | BA32: 2 | BB32: Medium | BC32: 3
A33: 0048-PIHNL | B33: Female | C33: 48 | D33: Yes | E33: 0 | F33: Los Angeles | G33: 90058 | H33: 34.001617 | I33: -118.22227 | J33: 5 | K33: 49 | L33: Offer B | M33: Yes | N33: 49.58 | O33: No | P33: No | Q33: N/A | R33: N/A | S33: N/A | T33: N/A | U33: N/A | V33: N/A | W33: N/A | X33: N/A | Y33: N/A | Z33: N/A | AA33: One Year | AB33: No | AC33: Bank Withdrawal | AD33: 20.45 | AE33: 900.9 | AF33: 0 | AG33: 0 | AH33: 2429.42 | AI33: 3330.32 | AJ33: Stayed | AM33: 0 | AN33: 1 | AO33: 0 | AP33: 49-72 months | AQ33: 40-49 | AR33: Low (<$30) | AT33: 3642 | AU33: 1 | AV33: 0 | AW33: 1 | AX33: 0 | AY33: 6 | AZ33: 06 | 49-72 months | BA33: 1 | BB33: Low | BC33: 4
A34: 0052-DCKON | B34: Male | C34: 28 | D34: Yes | E34: 0 | F34: Los Angeles | G34: 90063 | H34: 34.044271 | I34: -118.18524 | J34: 9 | K34: 66 | L34: None | M34: Yes | N34: 43.77 | O34: Yes | P34: Yes | Q34: Fiber Optic | R34: 41.0 | S34: Yes | T34: Yes | U34: Yes | V34: Yes | W34: Yes | X34: Yes | Y34: Yes | Z34: Yes | AA34: One Year | AB34: No | AC34: Bank Withdrawal | AD34: -2 | AE34: 7942.15 | AF34: 0 | AG34: 0 | AH34: 2888.82 | AI34: 10830.97 | AJ34: Stayed | AM34: 0 | AN34: 1 | AO34: 1 | AP34: 49-72 months | AQ34: Under 30 | AR34: Credit (<$0) | AS34: 8 | AT34: 55668 | AU34: 1 | AV34: 0 | AW34: 1 | AX34: 0 | AY34: 6 | AZ34: 06 | 49-72 months | BA34: 3 | BB34: Medium | BC34: 3
A35: 0052-YNYOT | B35: Female | C35: 28 | D35: No | E35: 0 | F35: Calexico | G35: 92231 | H35: 32.690654 | I35: -115.43122 | J35: 0 | K35: 67 | L35: None | M35: Yes | N35: 23.12 | O35: No | P35: No | Q35: N/A | R35: N/A | S35: N/A | T35: N/A | U35: N/A | V35: N/A | W35: N/A | X35: N/A | Y35: N/A | Z35: N/A | AA35: One Year | AB35: No | AC35: Bank Withdrawal | AD35: 20.55 | AE35: 1343.4 | AF35: 30.53 | AG35: 0 | AH35: 1549.04 | AI35: 2861.91 | AJ35: Stayed | AM35: 0 | AN35: 1 | AO35: 0 | AP35: 49-72 months | AQ35: Under 30 | AR35: Low (<$30) | AT35: 27804 | AU35: 1 | AV35: 0 | AW35: 1 | AX35: 0 | AY35: 6 | AZ35: 06 | 49-72 months | BA35: 2 | BB35: Medium | BC35: 3
A36: 0056-EPFBG | B36: Male | C36: 33 | D36: Yes | E36: 1 | F36: Redding | G36: 96003 | H36: 40.677649 | I36: -122.29467 | J36: 4 | K36: 20 | L36: None | M36: No | N36: N/A | O36: N/A | P36: Yes | Q36: Cable | R36: 22.0 | S36: Yes | T36: No | U36: Yes | V36: Yes | W36: No | X36: No | Y36: No | Z36: Yes | AA36: Two Year | AB36: Yes | AC36: Credit Card | AD36: 39.4 | AE36: 825.4 | AF36: 0 | AG36: 0 | AH36: 0 | AI36: 825.4 | AJ36: Stayed | AM36: 0 | AN36: 1 | AO36: 0 | AP36: 13-24 months | AQ36: 30-39 | AR36: $30-49 | AS36: 4 | AT36: 41476 | AU36: 1 | AV36: 0 | AW36: 1 | AX36: 0 | AY36: 3 | AZ36: 03 | 13-24 months | BA36: 0 | BB36: Low | BC36: 4
A37: 0057-QBUQH | B37: Female | C37: 31 | D37: No | E37: 3 | F37: San Martin | G37: 95046 | H37: 37.084697 | I37: -121.60642 | J37: 0 | K37: 43 | L37: None | M37: Yes | N37: 30.64 | O37: Yes | P37: No | Q37: N/A | R37: N/A | S37: N/A | T37: N/A | U37: N/A | V37: N/A | W37: N/A | X37: N/A | Y37: N/A | Z37: N/A | AA37: Two Year | AB37: Yes | AC37: Bank Withdrawal | AD37: 25.1 | AE37: 1070.15 | AF37: 0 | AG37: 0 | AH37: 1317.52 | AI37: 2387.67 | AJ37: Stayed | AM37: 0 | AN37: 1 | AO37: 0 | AP37: 37-48 months | AQ37: 30-39 | AR37: Low (<$30) | AT37: 5671 | AU37: 1 | AV37: 0 | AW37: 1 | AX37: 0 | AY37: 5 | AZ37: 05 | 37-48 months | BA37: 1 | BB37: Low | BC37: 4
A38: 0058-EVZWM | B38: Female | C38: 37 | D38: Yes | E38: 0 | F38: Stockton | G38: 95209 | H38: 38.044523 | I38: -121.34805 | J38: 2 | K38: 55 | L38: Offer B | M38: Yes | N38: 5.08 | O38: Yes | P38: Yes | Q38: Fiber Optic | R38: 9.0 | S38: Yes | T38: No | U38: No | V38: No | W38: Yes | X38: No | Y38: No | Z38: Yes | AA38: Month-to-Month | AB38: Yes | AC38: Bank Withdrawal | AD38: 89.8 | AE38: 4959.6 | AF38: 0 | AG38: 0 | AH38: 279.4 | AI38: 5239 | AJ38: Stayed | AM38: 0 | AN38: 1 | AO38: 0 | AP38: 49-72 months | AQ38: 30-39 | AR38: $70-89 | AS38: 3 | AT38: 30814 | AU38: 1 | AV38: 0 | AW38: 1 | AX38: 0 | AY38: 6 | AZ38: 06 | 49-72 months | BA38: 6 | BB38: Very High | BC38: 1
A39: 0060-FUALY | B39: Female | C39: 60 | D39: Yes | E39: 0 | F39: Los Angeles | G39: 90003 | H39: 33.964131 | I39: -118.27278 | J39: 4 | K39: 59 | L39: Offer B | M39: Yes | N39: 16.39 | O39: Yes | P39: Yes | Q39: Fiber Optic | R39: 14.0 | S39: Yes | T39: Yes | U39: No | V39: No | W39: Yes | X39: No | Y39: No | Z39: Yes | AA39: Month-to-Month | AB39: Yes | AC39: Bank Withdrawal | AD39: 94.75 | AE39: 5597.65 | AF39: 0 | AG39: 0 | AH39: 967.01 | AI39: 6564.66 | AJ39: Stayed | AM39: 0 | AN39: 1 | AO39: 0 | AP39: 49-72 months | AQ39: 60-69 | AR39: $90+ | AS39: 4 | AT39: 58198 | AU39: 1 | AV39: 0 | AW39: 1 | AX39: 0 | AY39: 6 | AZ39: 06 | 49-72 months | BA39: 6 | BB39: Very High | BC39: 1
A40: 0064-SUDOG | B40: Female | C40: 48 | D40: Yes | E40: 3 | F40: Huntington Park | G40: 90255 | H40: 33.97803 | I40: -118.21714 | J40: 3 | K40: 12 | L40: None | M40: Yes | N40: 19.28 | O40: No | P40: No | Q40: N/A | R40: N/A | S40: N/A | T40: N/A | U40: N/A | V40: N/A | W40: N/A | X40: N/A | Y40: N/A | Z40: N/A | AA40: Two Year | AB40: No | AC40: Bank Withdrawal | AD40: 20.3 | AE40: 224.5 | AF40: 0 | AG40: 0 | AH40: 231.36 | AI40: 455.86 | AJ40: Stayed | AM40: 0 | AN40: 1 | AO40: 0 | AP40: 7-12 months | AQ40: 40-49 | AR40: Low (<$30) | AT40: 78114 | AU40: 1 | AV40: 0 | AW40: 1 | AX40: 0 | AY40: 2 | AZ40: 02 | 7-12 months | BA40: 0 | BB40: Low | BC40: 4
...
